<?xml version='1.0' encoding='utf-8'?>
<robot name="pruning_robot">
  <link name="world" />
  <material name="grass_green">
    <color rgba="0.47058823529411764 0.6392156862745098 0.17254901960784313 1" />
  </material>
  <link name="rotation_correction_plate__base" />
  <link name="rotation_correction_plate__body">
    <visual>
      <material name="grass_green" />
      <origin rpy="0 0 0" xyz="0 0 0" />
      <geometry>
        <mesh filename="package://pruning_bt/meshes/end_effectors/rotation_correction_plate/RotationCorrectionPlate.STL" />
      </geometry>
    </visual>
    <collision>
      <origin rpy="0 0 0" xyz="0 0 0" />
      <geometry>
        <mesh filename="package://pruning_bt/meshes/end_effectors/rotation_correction_plate/RotationCorrectionPlate.STL" />
      </geometry>
    </collision>
    <inertial>
      <mass value="0.047" />
      <origin xyz="0.0 0.0 0.0" />
      <inertia ixx="0.0001" ixy="0.0" ixz="0.0" iyy="0.0001" iyz="0.0" izz="0.0001" />
    </inertial>
  </link>
  <link name="rotation_correction_plate__tool0" />
  <joint name="tool0--rotation_correction_plate__base" type="fixed">
    <origin rpy="0.0 0.0 0.0" xyz="0 0 0" />
    <parent link="tool0" />
    <child link="rotation_correction_plate__base" />
  </joint>
  <joint name="rotation_correction_plate__base--body" type="fixed">
    <origin rpy="0 0 0" xyz="0 0 0" />
    <parent link="rotation_correction_plate__base" />
    <child link="rotation_correction_plate__body" />
  </joint>
  <joint name="rotation_correction_plate__body--tool0" type="fixed">
    <origin rpy="0 0 0" xyz="0 0 0.01268" />
    <parent link="rotation_correction_plate__body" />
    <child link="rotation_correction_plate__tool0" />
  </joint>
  <material name="lavender">
    <color rgba="0.749 0.580 0.894 1" />
  </material>
  <link name="dovetail_male_mount__base" />
  <link name="dovetail_male_mount__body">
    <visual>
      <material name="lavender" />
      <origin rpy="0 0 0" xyz="0 0 0" />
      <geometry>
        <mesh filename="package://pruning_bt/meshes/end_effectors/dovetail/DovetailMale.STL" />
      </geometry>
    </visual>
    <collision>
      <origin rpy="0 0 0" xyz="0 0 0" />
      <geometry>
        <mesh filename="package://pruning_bt/meshes/end_effectors/dovetail/DovetailMale.STL" />
      </geometry>
    </collision>
    <inertial>
      <mass value="0.033" />
      <origin xyz="0.0 0.0 0.0" />
      <inertia ixx="0.0001" ixy="0.0" ixz="0.0" iyy="0.0001" iyz="0.0" izz="0.0001" />
    </inertial>
  </link>
  <link name="dovetail_male_mount__tool0" />
  <joint name="rotation_correction_plate__tool0--dovetail_male_mount__base" type="fixed">
    <origin rpy="0.0 0.0 0.0" xyz="0 0 0" />
    <parent link="rotation_correction_plate__tool0" />
    <child link="dovetail_male_mount__base" />
  </joint>
  <joint name="dovetail_male_mount__base--body" type="fixed">
    <origin rpy="0 0 0" xyz="0 0 0" />
    <parent link="dovetail_male_mount__base" />
    <child link="dovetail_male_mount__body" />
  </joint>
  <joint name="dovetail_male_mount__body--tool0" type="fixed">
    <origin rpy="0 0 0" xyz="0 0 0.02293" />
    <parent link="dovetail_male_mount__body" />
    <child link="dovetail_male_mount__tool0" />
  </joint>
  <material name="ochre">
    <color rgba="0.929 0.710 0.145 1" />
  </material>
  <link name="dovetail_female_mount__base" />
  <link name="dovetail_female_mount__body">
    <visual>
      <material name="ochre" />
      <origin rpy="0 0 0" xyz="0 0 0" />
      <geometry>
        <mesh filename="package://pruning_bt/meshes/end_effectors/dovetail/DovetailFemale.STL" />
      </geometry>
    </visual>
    <collision>
      <origin rpy="0 0 0" xyz="0 0 0" />
      <geometry>
        <mesh filename="package://pruning_bt/meshes/end_effectors/dovetail/DovetailFemale.STL" />
      </geometry>
    </collision>
    <inertial>
      <mass value="0.038" />
      <origin xyz="0.0 0.0 0.0" />
      <inertia ixx="0.0001" ixy="0.0" ixz="0.0" iyy="0.0001" iyz="0.0" izz="0.0001" />
    </inertial>
  </link>
  <link name="dovetail_female_mount__tool0" />
  <joint name="dovetail_male_mount__tool0--dovetail_female_mount__base" type="fixed">
    <origin rpy="0.0 0.0 0.0" xyz="0 0 0.0" />
    <parent link="dovetail_male_mount__tool0" />
    <child link="dovetail_female_mount__base" />
  </joint>
  <joint name="dovetail_female_mount__base--body" type="fixed">
    <origin rpy="0 0 0" xyz="0 0 0" />
    <parent link="dovetail_female_mount__base" />
    <child link="dovetail_female_mount__body" />
  </joint>
  <joint name="dovetail_female_mount__body--tool0" type="fixed">
    <origin rpy="0 0 0" xyz="0 0 0.008" />
    <parent link="dovetail_female_mount__body" />
    <child link="dovetail_female_mount__tool0" />
  </joint>
  <link name="mock_pruner__base">
    <visual>
      <material name="orange">
        <color rgba="1.0 0.4235294117647059 0.0392156862745098 1.0" />
      </material>
      <origin rpy="0 0 0" xyz="0 0 0" />
      <geometry>
        <mesh filename="package://pruning_bt/meshes/end_effectors/mock_pruner/MockPrunerNoToF.STL" />
      </geometry>
    </visual>
    <collision>
      <origin rpy="0 0 0" xyz="0 0 0" />
      <geometry>
        <mesh filename="package://pruning_bt/meshes/end_effectors/mock_pruner/MockPrunerNoToF.STL" />
      </geometry>
    </collision>
    <inertial>
      <mass value="0.256" />
      <origin xyz="0.0 0.0 0.0" />
      <inertia ixx="0.1" ixy="0.0" ixz="0.0" iyy="0.1" iyz="0.0" izz="0.1" />
    </inertial>
  </link>
  <link name="mock_pruner__camera0" />
  <link name="mock_pruner__tof0" />
  <link name="mock_pruner__tof1" />
  <link name="mock_pruner__tool0" />
  <joint name="dovetail_female_mount__tool0--mock_pruner__base" type="fixed">
    <origin rpy="0.0 0.0 0.0" xyz="0 0 0" />
    <parent link="dovetail_female_mount__tool0" />
    <child link="mock_pruner__base" />
  </joint>
  <joint name="mock_pruner__base--camera0" type="fixed">
    <origin rpy="0 0 0" xyz="-0.0017977 -0.0715747 0.0711646" />
    <parent link="mock_pruner__base" />
    <child link="mock_pruner__camera0" />
  </joint>
  <joint name="mock_pruner__base--tof0" type="fixed">
    <origin rpy="0 0 0" xyz="0.04891 0.005 0.14237" />
    <parent link="mock_pruner__base" />
    <child link="mock_pruner__tof0" />
  </joint>
  <joint name="mock_pruner__base--tof1" type="fixed">
    <origin rpy="0 0 0" xyz="-0.04891 0.005 0.14237" />
    <parent link="mock_pruner__base" />
    <child link="mock_pruner__tof1" />
  </joint>
  <joint name="mock_pruner__base--tool0" type="fixed">
    <origin rpy="0 0 0" xyz="0.0 0.0050825 0.1601525" />
    <parent link="mock_pruner__base" />
    <child link="mock_pruner__tool0" />
  </joint>
  <ros2_control name="pruning_robot" type="system">
    <hardware>
      <plugin>ur_robot_driver/URPositionHardwareInterface</plugin>
      <param name="robot_ip">169.254.177.230</param>
      <param name="script_filename">/opt/ros/humble/share/ur_client_library/resources/external_control.urscript</param>
      <param name="output_recipe_filename">/opt/ros/humble/share/ur_robot_driver/resources/rtde_output_recipe.txt</param>
      <param name="input_recipe_filename">/opt/ros/humble/share/ur_robot_driver/resources/rtde_input_recipe.txt</param>
      <param name="headless_mode">True</param>
      <param name="reverse_port">50001</param>
      <param name="script_sender_port">50002</param>
      <param name="reverse_ip">0.0.0.0</param>
      <param name="script_command_port">50004</param>
      <param name="trajectory_port">50003</param>
      <param name="tf_prefix"></param>
      <param name="non_blocking_read">True</param>
      <param name="servoj_gain">2000</param>
      <param name="servoj_lookahead_time">0.03</param>
      <param name="use_tool_communication">False</param>
      <param name="kinematics/hash">calib_12788084448423163542</param>
      <param name="tool_voltage">0</param>
      <param name="tool_parity">0</param>
      <param name="tool_baud_rate">115200</param>
      <param name="tool_stop_bits">1</param>
      <param name="tool_rx_idle_chars">1.5</param>
      <param name="tool_tx_idle_chars">3.5</param>
      <param name="tool_device_name">/tmp/ttyUR</param>
      <param name="tool_tcp_port">54321</param>
      <param name="keep_alive_count">2</param>
    </hardware>
    <joint name="shoulder_pan_joint">
      <command_interface name="position" />
      <command_interface name="velocity" />
      <state_interface name="position">
        <param name="initial_value">0.0</param>
      </state_interface>
      <state_interface name="velocity" />
      <state_interface name="effort" />
    </joint>
    <joint name="shoulder_lift_joint">
      <command_interface name="position" />
      <command_interface name="velocity" />
      <state_interface name="position">
        <param name="initial_value">-1.83259571459</param>
      </state_interface>
      <state_interface name="velocity" />
      <state_interface name="effort" />
    </joint>
    <joint name="elbow_joint">
      <command_interface name="position" />
      <command_interface name="velocity" />
      <state_interface name="position">
        <param name="initial_value">2.09439510239</param>
      </state_interface>
      <state_interface name="velocity" />
      <state_interface name="effort" />
    </joint>
    <joint name="wrist_1_joint">
      <command_interface name="position" />
      <command_interface name="velocity" />
      <state_interface name="position">
        <param name="initial_value">2.87979326579</param>
      </state_interface>
      <state_interface name="velocity" />
      <state_interface name="effort" />
    </joint>
    <joint name="wrist_2_joint">
      <command_interface name="position" />
      <command_interface name="velocity" />
      <state_interface name="position">
        <param name="initial_value">-1.57079632679</param>
      </state_interface>
      <state_interface name="velocity" />
      <state_interface name="effort" />
    </joint>
    <joint name="wrist_3_joint">
      <command_interface name="position" />
      <command_interface name="velocity" />
      <state_interface name="position">
        <param name="initial_value">0.0</param>
      </state_interface>
      <state_interface name="velocity" />
      <state_interface name="effort" />
    </joint>
    <sensor name="tcp_fts_sensor">
      <state_interface name="force.x" />
      <state_interface name="force.y" />
      <state_interface name="force.z" />
      <state_interface name="torque.x" />
      <state_interface name="torque.y" />
      <state_interface name="torque.z" />
    </sensor>
    <sensor name="tcp_pose">
      <state_interface name="position.x" />
      <state_interface name="position.y" />
      <state_interface name="position.z" />
      <state_interface name="orientation.x" />
      <state_interface name="orientation.y" />
      <state_interface name="orientation.z" />
      <state_interface name="orientation.w" />
    </sensor>
    <gpio name="speed_scaling">
      <state_interface name="speed_scaling_factor" />
      <param name="initial_speed_scaling_factor">1</param>
      <command_interface name="target_speed_fraction_cmd" />
      <command_interface name="target_speed_fraction_async_success" />
    </gpio>
    <gpio name="gpio">
      <command_interface name="standard_digital_output_cmd_0" />
      <command_interface name="standard_digital_output_cmd_1" />
      <command_interface name="standard_digital_output_cmd_2" />
      <command_interface name="standard_digital_output_cmd_3" />
      <command_interface name="standard_digital_output_cmd_4" />
      <command_interface name="standard_digital_output_cmd_5" />
      <command_interface name="standard_digital_output_cmd_6" />
      <command_interface name="standard_digital_output_cmd_7" />
      <command_interface name="standard_digital_output_cmd_8" />
      <command_interface name="standard_digital_output_cmd_9" />
      <command_interface name="standard_digital_output_cmd_10" />
      <command_interface name="standard_digital_output_cmd_11" />
      <command_interface name="standard_digital_output_cmd_12" />
      <command_interface name="standard_digital_output_cmd_13" />
      <command_interface name="standard_digital_output_cmd_14" />
      <command_interface name="standard_digital_output_cmd_15" />
      <command_interface name="standard_digital_output_cmd_16" />
      <command_interface name="standard_digital_output_cmd_17" />
      <command_interface name="standard_analog_output_cmd_0" />
      <command_interface name="standard_analog_output_cmd_1" />
      <command_interface name="analog_output_domain_cmd" />
      <command_interface name="tool_voltage_cmd" />
      <command_interface name="io_async_success" />
      <state_interface name="digital_output_0" />
      <state_interface name="digital_output_1" />
      <state_interface name="digital_output_2" />
      <state_interface name="digital_output_3" />
      <state_interface name="digital_output_4" />
      <state_interface name="digital_output_5" />
      <state_interface name="digital_output_6" />
      <state_interface name="digital_output_7" />
      <state_interface name="digital_output_8" />
      <state_interface name="digital_output_9" />
      <state_interface name="digital_output_10" />
      <state_interface name="digital_output_11" />
      <state_interface name="digital_output_12" />
      <state_interface name="digital_output_13" />
      <state_interface name="digital_output_14" />
      <state_interface name="digital_output_15" />
      <state_interface name="digital_output_16" />
      <state_interface name="digital_output_17" />
      <state_interface name="digital_input_0" />
      <state_interface name="digital_input_1" />
      <state_interface name="digital_input_2" />
      <state_interface name="digital_input_3" />
      <state_interface name="digital_input_4" />
      <state_interface name="digital_input_5" />
      <state_interface name="digital_input_6" />
      <state_interface name="digital_input_7" />
      <state_interface name="digital_input_8" />
      <state_interface name="digital_input_9" />
      <state_interface name="digital_input_10" />
      <state_interface name="digital_input_11" />
      <state_interface name="digital_input_12" />
      <state_interface name="digital_input_13" />
      <state_interface name="digital_input_14" />
      <state_interface name="digital_input_15" />
      <state_interface name="digital_input_16" />
      <state_interface name="digital_input_17" />
      <state_interface name="standard_analog_output_0" />
      <state_interface name="standard_analog_output_1" />
      <state_interface name="standard_analog_input_0" />
      <state_interface name="standard_analog_input_1" />
      <state_interface name="analog_io_type_0" />
      <state_interface name="analog_io_type_1" />
      <state_interface name="analog_io_type_2" />
      <state_interface name="analog_io_type_3" />
      <state_interface name="tool_mode" />
      <state_interface name="tool_output_voltage" />
      <state_interface name="tool_output_current" />
      <state_interface name="tool_temperature" />
      <state_interface name="tool_analog_input_0" />
      <state_interface name="tool_analog_input_1" />
      <state_interface name="tool_analog_input_type_0" />
      <state_interface name="tool_analog_input_type_1" />
      <state_interface name="robot_mode" />
      <state_interface name="robot_status_bit_0" />
      <state_interface name="robot_status_bit_1" />
      <state_interface name="robot_status_bit_2" />
      <state_interface name="robot_status_bit_3" />
      <state_interface name="safety_mode" />
      <state_interface name="safety_status_bit_0" />
      <state_interface name="safety_status_bit_1" />
      <state_interface name="safety_status_bit_2" />
      <state_interface name="safety_status_bit_3" />
      <state_interface name="safety_status_bit_4" />
      <state_interface name="safety_status_bit_5" />
      <state_interface name="safety_status_bit_6" />
      <state_interface name="safety_status_bit_7" />
      <state_interface name="safety_status_bit_8" />
      <state_interface name="safety_status_bit_9" />
      <state_interface name="safety_status_bit_10" />
      <state_interface name="program_running" />
    </gpio>
    <gpio name="payload">
      <command_interface name="mass" />
      <command_interface name="cog.x" />
      <command_interface name="cog.y" />
      <command_interface name="cog.z" />
      <command_interface name="payload_async_success" />
    </gpio>
    <gpio name="resend_robot_program">
      <command_interface name="resend_robot_program_cmd" />
      <command_interface name="resend_robot_program_async_success" />
    </gpio>
    <gpio name="hand_back_control">
      <command_interface name="hand_back_control_cmd" />
      <command_interface name="hand_back_control_async_success" />
    </gpio>
    <gpio name="zero_ftsensor">
      <command_interface name="zero_ftsensor_cmd" />
      <command_interface name="zero_ftsensor_async_success" />
    </gpio>
    <gpio name="system_interface">
      <state_interface name="initialized" />
    </gpio>
    <gpio name="get_robot_software_version">
      <state_interface name="get_version_major" />
      <state_interface name="get_version_minor" />
      <state_interface name="get_version_build" />
      <state_interface name="get_version_bugfix" />
    </gpio>
  </ros2_control>
  <link name="base_link" />
  <link name="base_link_inertia">
    <visual>
      <origin rpy="0 0 3.141592653589793" xyz="0 0 0" />
      <geometry>
        <mesh filename="package://ur_description/meshes/ur5e/visual/base.dae" />
      </geometry>
    </visual>
    <collision>
      <origin rpy="0 0 3.141592653589793" xyz="0 0 0" />
      <geometry>
        <mesh filename="package://ur_description/meshes/ur5e/collision/base.stl" />
      </geometry>
    </collision>
    <inertial>
      <mass value="4.0" />
      <origin rpy="0 0 0" xyz="0 0 0" />
      <inertia ixx="0.00443333156" ixy="0.0" ixz="0.0" iyy="0.00443333156" iyz="0.0" izz="0.0072" />
    </inertial>
  </link>
  <link name="shoulder_link">
    <visual>
      <origin rpy="0 0 3.141592653589793" xyz="0 0 0" />
      <geometry>
        <mesh filename="package://ur_description/meshes/ur5e/visual/shoulder.dae" />
      </geometry>
    </visual>
    <collision>
      <origin rpy="0 0 3.141592653589793" xyz="0 0 0" />
      <geometry>
        <mesh filename="package://ur_description/meshes/ur5e/collision/shoulder.stl" />
      </geometry>
    </collision>
    <inertial>
      <mass value="3.761" />
      <origin rpy="0 0 0" xyz="0.0 -0.00193 -0.02561" />
      <inertia ixx="0.010267499999999999" ixy="0" ixz="0" iyy="0.010267499999999999" iyz="0" izz="0.00666" />
    </inertial>
  </link>
  <link name="upper_arm_link">
    <visual>
      <origin rpy="1.5707963267948966 0 -1.5707963267948966" xyz="0 0 0.138" />
      <geometry>
        <mesh filename="package://ur_description/meshes/ur5e/visual/upperarm.dae" />
      </geometry>
    </visual>
    <collision>
      <origin rpy="1.5707963267948966 0 -1.5707963267948966" xyz="0 0 0.138" />
      <geometry>
        <mesh filename="package://ur_description/meshes/ur5e/collision/upperarm.stl" />
      </geometry>
    </collision>
    <inertial>
      <mass value="8.058" />
      <origin rpy="0 1.570796326794897 0" xyz="-0.2125 0.0 0.11336" />
      <inertia ixx="0.13388583541666665" ixy="0" ixz="0" iyy="0.13388583541666665" iyz="0" izz="0.0151074" />
    </inertial>
  </link>
  <link name="forearm_link">
    <visual>
      <origin rpy="1.5707963267948966 0 -1.5707963267948966" xyz="0 0 0.007" />
      <geometry>
        <mesh filename="package://ur_description/meshes/ur5e/visual/forearm.dae" />
      </geometry>
    </visual>
    <collision>
      <origin rpy="1.5707963267948966 0 -1.5707963267948966" xyz="0 0 0.007" />
      <geometry>
        <mesh filename="package://ur_description/meshes/ur5e/collision/forearm.stl" />
      </geometry>
    </collision>
    <inertial>
      <mass value="2.846" />
      <origin rpy="0 1.570796326794897 0" xyz="-0.2422 0.0 0.0265" />
      <inertia ixx="0.03120936758333333" ixy="0" ixz="0" iyy="0.03120936758333333" iyz="0" izz="0.004095" />
    </inertial>
  </link>
  <link name="wrist_1_link">
    <visual>
      <origin rpy="1.5707963267948966 0 0" xyz="0 0 -0.127" />
      <geometry>
        <mesh filename="package://ur_description/meshes/ur5e/visual/wrist1.dae" />
      </geometry>
    </visual>
    <collision>
      <origin rpy="1.5707963267948966 0 0" xyz="0 0 -0.127" />
      <geometry>
        <mesh filename="package://ur_description/meshes/ur5e/collision/wrist1.stl" />
      </geometry>
    </collision>
    <inertial>
      <mass value="1.37" />
      <origin rpy="0 0 0" xyz="0.0 -0.01634 -0.0018" />
      <inertia ixx="0.0025599" ixy="0" ixz="0" iyy="0.0025599" iyz="0" izz="0.0021942" />
    </inertial>
  </link>
  <link name="wrist_2_link">
    <visual>
      <origin rpy="0 0 0" xyz="0 0 -0.0997" />
      <geometry>
        <mesh filename="package://ur_description/meshes/ur5e/visual/wrist2.dae" />
      </geometry>
    </visual>
    <collision>
      <origin rpy="0 0 0" xyz="0 0 -0.0997" />
      <geometry>
        <mesh filename="package://ur_description/meshes/ur5e/collision/wrist2.stl" />
      </geometry>
    </collision>
    <inertial>
      <mass value="1.3" />
      <origin rpy="0 0 0" xyz="0.0 0.01634 -0.0018" />
      <inertia ixx="0.0025599" ixy="0" ixz="0" iyy="0.0025599" iyz="0" izz="0.0021942" />
    </inertial>
  </link>
  <link name="wrist_3_link">
    <visual>
      <origin rpy="1.5707963267948966 0 0" xyz="0 0 -0.0989" />
      <geometry>
        <mesh filename="package://ur_description/meshes/ur5e/visual/wrist3.dae" />
      </geometry>
    </visual>
    <collision>
      <origin rpy="1.5707963267948966 0 0" xyz="0 0 -0.0989" />
      <geometry>
        <mesh filename="package://ur_description/meshes/ur5e/collision/wrist3.stl" />
      </geometry>
    </collision>
    <inertial>
      <mass value="0.365" />
      <origin rpy="0 0 0" xyz="0.0 0.0 -0.001159" />
      <inertia ixx="9.890414008333333e-05" ixy="0" ixz="0" iyy="9.890414008333333e-05" iyz="0" izz="0.0001321171875" />
    </inertial>
  </link>
  <joint name="base_joint" type="fixed">
    <origin rpy="0 0 0" xyz="0 0 0" />
    <parent link="amiga__tool0" />
    <child link="base_link" />
  </joint>
  <joint name="base_link-base_link_inertia" type="fixed">
    <parent link="base_link" />
    <child link="base_link_inertia" />
    <origin rpy="0 0 3.141592653589793" xyz="0 0 0" />
  </joint>
  <joint name="shoulder_pan_joint" type="revolute">
    <parent link="base_link_inertia" />
    <child link="shoulder_link" />
    <origin rpy="0 0 0" xyz="0 0 0.1625" />
    <axis xyz="0 0 1" />
    <limit effort="150.0" lower="-6.283185307179586" upper="6.283185307179586" velocity="3.141592653589793" />
    <dynamics damping="0" friction="0" />
  </joint>
  <joint name="shoulder_lift_joint" type="revolute">
    <parent link="shoulder_link" />
    <child link="upper_arm_link" />
    <origin rpy="1.570796327 0 0" xyz="0 0 0" />
    <axis xyz="0 0 1" />
    <limit effort="150.0" lower="-6.283185307179586" upper="6.283185307179586" velocity="3.141592653589793" />
    <dynamics damping="0" friction="0" />
  </joint>
  <joint name="elbow_joint" type="revolute">
    <parent link="upper_arm_link" />
    <child link="forearm_link" />
    <origin rpy="0 0 0" xyz="-0.425 0 0" />
    <axis xyz="0 0 1" />
    <limit effort="150.0" lower="-3.141592653589793" upper="3.141592653589793" velocity="3.141592653589793" />
    <dynamics damping="0" friction="0" />
  </joint>
  <joint name="wrist_1_joint" type="revolute">
    <parent link="forearm_link" />
    <child link="wrist_1_link" />
    <origin rpy="0 0 0" xyz="-0.3922 0 0.1333" />
    <axis xyz="0 0 1" />
    <limit effort="28.0" lower="-6.283185307179586" upper="6.283185307179586" velocity="3.141592653589793" />
    <dynamics damping="0" friction="0" />
  </joint>
  <joint name="wrist_2_joint" type="revolute">
    <parent link="wrist_1_link" />
    <child link="wrist_2_link" />
    <origin rpy="1.570796327 0 0" xyz="0 -0.0997 -2.044881182297852e-11" />
    <axis xyz="0 0 1" />
    <limit effort="28.0" lower="-6.283185307179586" upper="6.283185307179586" velocity="3.141592653589793" />
    <dynamics damping="0" friction="0" />
  </joint>
  <joint name="wrist_3_joint" type="revolute">
    <parent link="wrist_2_link" />
    <child link="wrist_3_link" />
    <origin rpy="1.570796326589793 3.141592653589793 3.141592653589793" xyz="0 0.0996 -2.042830148012698e-11" />
    <axis xyz="0 0 1" />
    <limit effort="28.0" lower="-6.283185307179586" upper="6.283185307179586" velocity="3.141592653589793" />
    <dynamics damping="0" friction="0" />
  </joint>
  <link name="ft_frame" />
  <joint name="wrist_3_link-ft_frame" type="fixed">
    <parent link="wrist_3_link" />
    <child link="ft_frame" />
    <origin rpy="3.141592653589793 0 0" xyz="0 0 0" />
  </joint>
  <link name="base" />
  <joint name="base_link-base_fixed_joint" type="fixed">
    <origin rpy="0 0 3.141592653589793" xyz="0 0 0" />
    <parent link="base_link" />
    <child link="base" />
  </joint>
  <link name="flange" />
  <joint name="wrist_3-flange" type="fixed">
    <parent link="wrist_3_link" />
    <child link="flange" />
    <origin rpy="0 -1.5707963267948966 -1.5707963267948966" xyz="0 0 0" />
  </joint>
  <link name="tool0" />
  <joint name="flange-tool0" type="fixed">
    <origin rpy="1.5707963267948966 0 1.5707963267948966" xyz="0 0 0" />
    <parent link="flange" />
    <child link="tool0" />
  </joint>
  <material name="LightLightGrey">
    <color rgba="0.941 0.941 0.941 1.0" />
  </material>
  <link name="amiga__base" />
  <link name="amiga__body">
    <visual>
      <origin rpy="0.0 0.0 0.0" xyz="0.0 0.0 0.0" />
      <geometry>
        <mesh filename="package://pruning_bt/meshes/base_mounts/farm-ng/amiga/frame_on_amiga_v2_simplified.stl" />
      </geometry>
      <material name="LightLightGrey" />
    </visual>
    <collision>
      <origin rpy="0.0 0.0 0.0" xyz="0.0 0.0 0.499053035" />
      <geometry>
        <box size="1.132 0.8 0.99810607" />
      </geometry>
    </collision>
    <collision>
      <origin rpy="0.0 0.0 0.0" xyz="0.0 -0.12 0.99810607" />
      <geometry>
        <box size="1.132 0.6 0.2" />
      </geometry>
    </collision>
    <collision>
      <origin rpy="0.0 0.0 0.0" xyz="0.44099999999999995 0.08333333333333333 1.19810607" />
      <geometry>
        <box size="0.25 0.25 0.25" />
      </geometry>
    </collision>
    <inertial>
      <origin rpy="0 0 0" xyz="0.0 0.0 0.0" />
      <mass value="40.0" />
      <inertia ixx="5.454052423236149" ixy="0.0" ixz="0.0" iyy="7.592132423236148" iyz="0.0" izz="6.404746666666665" />
    </inertial>
  </link>
  <link name="amiga__tool0" />
  <joint name="world--amiga__base" type="fixed">
    <origin rpy="0 0 " xyz="0 0 0" />
    <parent link="world" />
    <child link="amiga__base" />
  </joint>
  <joint name="amiga__base--amiga__body" type="fixed">
    <origin rpy="0 0 0" xyz="0 0 0" />
    <parent link="amiga__base" />
    <child link="amiga__body" />
  </joint>
  <joint name="amiga__body--amiga__tool0" type="fixed">
    <origin rpy="0.0 0.0 -3.9269908169872414" xyz="-0.225 0.323256 0.99810607" />
    <parent link="amiga__body" />
    <child link="amiga__tool0" />
  </joint>
</robot>